Это специальный синтаксис для работы с промисами

```table-of-contents
```
# async - Асинхронные функции
```js
async function f() {
	return 1;
}
```

Здесь всё просто. Это ключевое слово обязывает функцию вернуть успешно завершенный промис. Значнеия других типов автоматически оборачиваются в промис.

# await
Может использоваться только внутри async-функции. Иначе будет ошибка синтаксиса. Заставляет интерпретатор JS ждать, пока исполнится промис, записманный справа от await. Во время отого ожидания движок JS может заниматься другими делами: выполнять прочие скрипты, обрабатывать события и т.п.

```javascript
async function f() {

  let promise = new Promise((resolve, reject) => {
    setTimeout(() => resolve("готово!"), 1000)
  });

  let result = await promise; // будет ждать, пока промис не выполнится (*)

  alert(result); // "готово!"
}

f();
```

В данном примере выполнение функции остановится на строке `(*)` до тех пор, пока промис не выполнится. Это произойдёт через секунду после запуска функции. После чего в переменную `result` будет записан результат выполнения промиса, и браузер отобразит alert-окно «готово!».

# Асинхронные методы классов
Для объявления асинхронного метода достаточно написать `async` перед именем:

```javascript
class Waiter {
  async wait() {
    return await Promise.resolve(1);
  }
}

new Waiter()
  .wait()
  .then(alert); // 1
```

Как и в случае с асинхронными функциями, такой метод гарантированно возвращает промис, и в его теле можно использовать `await`.

# Обработка ошибок
Когда промис завершается успешно, `await promise` возвращает результат. Когда завершается с ошибкой – будет выброшено исключение. Как если бы на этом месте находилось выражение `throw`.

Такой код:

```javascript
async function f() {
  await Promise.reject(new Error("Упс!"));
}
```

Делает то же самое, что и такой:

```javascript
async function f() {
  throw new Error("Упс!");
}
```

Но есть отличие: на практике промис может завершиться с ошибкой не сразу, а через некоторое время. В этом случае будет задержка, а затем `await` выбросит исключение.

Такие ошибки можно ловить, используя `try..catch`, как с обычным `throw`:

```javascript
async function f() {

  try {
    let response = await fetch('http://no-such-url');
  } catch(err) {
    alert(err); // TypeError: failed to fetch
  }
}

f();
```

В случае ошибки выполнение `try` прерывается и управление прыгает в начало блока `catch`. Блоком `try` можно обернуть несколько строк:

```javascript
async function f() {

  try {
    let response = await fetch('/no-user-here');
    let user = await response.json();
  } catch(err) {
    // перехватит любую ошибку в блоке try: и в fetch, и в response.json
    alert(err);
  }
}

f();
```

Если у нас нет `try..catch`, асинхронная функция будет возвращать завершившийся с ошибкой промис (в состоянии `rejected`). В этом случае мы можем использовать метод `.catch` промиса, чтобы обработать ошибку:

```javascript
async function f() {
  let response = await fetch('http://no-such-url');
}

// f() вернёт промис в состоянии rejected
f().catch(alert); // TypeError: failed to fetch // (*)
```

Если забыть добавить `.catch`, то будет сгенерирована ошибка «Uncaught promise error» и информация об этом будет выведена в консоль. Такие ошибки можно поймать глобальным обработчиком,