```table-of-contents
```
## Типы ошибок
- `Syntax error` (Синтаксические ошибки)
	- Нарушение правил языка. Например, лишняя скобка или запятая вместо точки. Это как будто бред шизофреника.
```js
let func = function ());
                      ^
// Syntax error, лишняя скобка
```
- `Reference error`
	- Если вызвать функцию без её объявления. Это как назвать кого-то чужим именем.
```js
let a = 42;
console.log(b);
            ^

// Reference error, переменная b не объявлена
```
- `Type error` (Ошибка типизации)
	- Это как попросить кошку постирать бельё. Возможно, вы хотели попросить это сделать своего друга. Или вот так:
```js
const length = 12;
const num = lenght(54); // Type error
            ^
// Здесь length это название переменной, а не функции, а мы ее пытаемся вызвать, как функцию
```

- `Логическая ошибка`. Злейшее зло. Например, переводим температуру из фаренгейта в цельсий
```js
const fahrToCelsius = (fahr) => {
	return fahr - 32 * 5/9;
}

console.log(fahrToCelsius(50)); // 32.2222222222 вместо 10
// Забыли обернуть (fahr - 32) в скобки и поэтому компьютер снгачала перемножил 32 и 5/9 в результате выдав ошибку. 
```

## try, catch, finally
Пробуем выполнить код в `try`, обрабатываем ошибки в `catch`, если такие возникнут, блок `finally` выполняется ВСЕГДА, вне зависимости от того, была ли поймана ошибка.

Есть Нюанс, если функция отложенная (например, `SetTimeout`), то `try/catch` надо запихнуть ВНУТРЬ отложенной функции, иначе она не обработается. Если `SetTimeout` поместить внутрь `try`, то он ничего не поймает ибо выполнение не будет во время исполнения блока `try`, нужно их расположить внутри `SetTimeout`, чтобы обработка происходила именно во время исполнения функции.

```js
let res = 0;
SetTimeout(function () {
	try {
		res = 5 / d;
		conaole.log(res);
	}
	catch(error) {
		consol.log(error);
	}
	finally() {
		// обязательный к выполнени код
	}
}, 0);
```

В блоке `catch` аргументом передается объект `error`, который содержит следующие свойства:
- name - название ошибки
- message - текст ошибки
- stack - стек вызова до возникновения ошибки (нестандартное свойство)

Объект `error` можно и не указывать, если нам не нужно обрабатывать его. 

## throw
`throw <объект ошибки>`

Можно выбрасывать свои ошибки, это может быть примитив, но лучше использовать стандартные объекты ошибок:
- Error - для общих ошибок
- SyntaxError
- TypeError
- ReferenceError

```js
let err1 = new Error("Просто ошибка");
let err2 = new Error("Еще одна ошибка");

throw err1;
throw new SyntaxError("Ататат!");
```

```js
const divZero = new Error('Cannot divide by zero!');

function div(a, b) {
  if (b === 0) {
    throw divZero;
  }
  return a / b;
}

let res = 0;

try {
  res = div(1, 0);
  console.log(res);
}
catch (error) {
  console.log(error.name); // Error
  console.log(error.message); // Cannot divide by zero!
}
```

## Проброс исключений
Блок `catch` отлавливает все ошибки без исключений. А что если мы хотим, чтобы он обрабатывал только определенный тип ошибок, а если случился другой тип, то он передавался бы внешнему блоку `catch`?
Это называется пробросом исключений. Внутренний блок `catch` должен содержать `if`, который проверяет, а нужный ли тип ошибки поступил. Если да -- обрабатываем его. Если нет, то выбрасываем объект ошибки наружу.

Есть простое правило:

**Блок `catch` должен обрабатывать только те ошибки, которые ему известны, и «пробрасывать» все остальные.**

```js
catch(error) {
	if (error.name == "Error") {
		// обработка ошибки
	} else {
		throw error;
	}
}
```

## Собственные типы ошибок

Можно создать класс с полями `name` и `message` (можно и без них, но лучше с ними для совместимости со стандартными объектами ошибок). И на его основе создавать свои ошибки

```js
class CustomError {
  name = 'Custom Error';

  constructor (msg = 'Message of custom error!') {
    this.message = msg;
  }
}

const divZero = new CustomError('Nooooooo');

function div(a, b) {
  if (b === 0) {
    throw divZero;
  }
  return a / b;
}

let res = 0;

try {
  res = div(1, 0);
  console.log(res);
}
catch (error) {
  console.log(error.name); // Custom Error
  console.log(error.message); // Noooooooo
}
```

Желательно, чтобы было также свойство `stack`. Можно также заводить собственный поля. Технически для выброса ошибок можно использовать любые классы, наследоваться от `Error` не обязательно. Но если таки использовать наследование, то появляется возможность идентификации объектов ошибок посредством `obj instanceof Error`. Так что лучше применять наследование.

По мере роста приложения, наши собственные ошибки образуют иерархию, например, `HttpTimeoutError` может наследовать от `HttpError` и так далее.

```javascript
// "Псевдокод" встроенного класса Error, определённого самим JavaScript
class Error {
  constructor(message) {
    this.message = message;
    this.name = "Error"; // (разные имена для разных встроенных классов ошибок)
    this.stack = <стек вызовов>; // нестандартное свойство, но обычно поддерживается
  }
}
```

```javascript
class ValidationError extends Error {
  constructor(message) {
    super(message); // (1)
    this.name = "ValidationError"; // (2)
  }
}

function test() {
  throw new ValidationError("Упс!");
}

try {
  test();
} catch(err) {
  alert(err.message); // Упс!
  alert(err.name); // ValidationError
  alert(err.stack); // список вложенных вызовов с номерами строк для каждого
}
```

Обратите внимание: в строке `(1)` вызываем родительский конструктор. JavaScript требует от нас вызова `super` в дочернем конструкторе, так что это обязательно. Родительский конструктор устанавливает свойство `message`.

Родительский конструктор также устанавливает свойство `name` для `"Error"`, поэтому в строке `(2)` мы сбрасываем его на правильное значение.

## Дальнейшее наследование

Класс `ValidationError` является слишком общим. Много что может пойти не так. Свойство может отсутствовать или иметь неверный формат (например, строка как значение возраста `age`). Поэтому для отсутствующих свойств сделаем более конкретный класс `PropertyRequiredError`. Он будет нести дополнительную информацию о свойстве, которое отсутствует.

```javascript
class ValidationError extends Error {
  constructor(message) {
    super(message);
    this.name = "ValidationError";
  }
}

class PropertyRequiredError extends ValidationError {
  constructor(property) {
    super("Нет свойства: " + property);
    this.name = "PropertyRequiredError";
    this.property = property;
  }
}

// Применение
function readUser(json) {
  let user = JSON.parse(json);

  if (!user.age) {
    throw new PropertyRequiredError("age");
  }
  if (!user.name) {
    throw new PropertyRequiredError("name");
  }

  return user;
}

// Рабочий пример с try..catch

try {
  let user = readUser('{ "age": 25 }');
} catch (err) {
  if (err instanceof ValidationError) {
    alert("Неверные данные: " + err.message); // Неверные данные: Нет свойства: name
    alert(err.name); // PropertyRequiredError
    alert(err.property); // name
  } else if (err instanceof SyntaxError) {
    alert("Ошибка синтаксиса JSON: " + err.message);
  } else {
    throw err; // неизвестная ошибка, повторно выбросит исключение
  }
}
```

Новый класс `PropertyRequiredError` очень просто использовать: необходимо указать только имя свойства `new PropertyRequiredError(property)`. Сообщение для пользователя `message` генерируется конструктором.

Обратите внимание, что свойство `this.name` в конструкторе `PropertyRequiredError` снова присвоено вручную. Правда, немного утомительно – присваивать `this.name = <class name>` в каждом классе пользовательской ошибки. Можно этого избежать, если сделать наш собственный «базовый» класс ошибки, который будет ставить `this.name = this.constructor.name`. И затем наследовать все ошибки уже от него.

Давайте назовём его `MyError`.

Вот упрощённый код с `MyError` и другими пользовательскими классами ошибок:

```javascript
class MyError extends Error {
  constructor(message) {
    super(message);
    this.name = this.constructor.name;
  }
}

class ValidationError extends MyError { }

class PropertyRequiredError extends ValidationError {
  constructor(property) {
    super("Нет свойства: " + property);
    this.property = property;
  }
}

// name корректное
alert( new PropertyRequiredError("field").name ); // PropertyRequiredError
```

Теперь пользовательские ошибки стали намного короче, особенно `ValidationError`, так как мы избавились от строки `"this.name = ..."` в конструкторе.

## Обёртывание исключений

Иногда нужно обрабатывать не каждое подряд исключение, а оббобщить их в ккаоую-то более высокоуровневую группу. Например, в примерах выше, вместо Ошибок Валидации и Отсутствия данных можно создать общую Ошибку Чтения и выбрасывать её, а исходную причину ошибки созхранять в собственном свойстве, например, `cause`

```js
class ReadError extends Error {
  constructor(message, cause) {
    super(message);
    this.cause = cause;
    this.name = 'ReadError';
  }
}

class ValidationError extends Error { /*...*/ }
class PropertyRequiredError extends ValidationError { /* ... */ }

function validateUser(user) {
  if (!user.age) {
    throw new PropertyRequiredError("age");
  }

  if (!user.name) {
    throw new PropertyRequiredError("name");
  }
}

function readUser(json) {
  let user;

  try {
    user = JSON.parse(json);
  } catch (err) {
    if (err instanceof SyntaxError) {
      throw new ReadError("Синтаксическая ошибка", err);
    } else {
      throw err;
    }
  }

  try {
    validateUser(user);
  } catch (err) {
    if (err instanceof ValidationError) {
      throw new ReadError("Ошибка валидации", err);
    } else {
      throw err;
    }
  }

}

try {
  readUser('{bad json}');
} catch (e) {
  if (e instanceof ReadError) {
    alert(e);
    // Исходная ошибка: SyntaxError:Unexpected token b in JSON at position 1
    alert("Исходная ошибка: " + e.cause);
  } else {
    throw e;
  }
}
```

В приведённом выше коде `readUser` работает так, как описано – функция распознаёт синтаксические ошибки и ошибки валидации и выдаёт вместо них ошибки `ReadError` (неизвестные ошибки, как обычно, пробрасываются).

Внешний код проверяет только `instanceof ReadError`. Не нужно перечислять все возможные типы ошибок

Этот подход называется «обёртывание исключений», потому что мы берём «исключения низкого уровня» и «оборачиваем» их в `ReadError`, который является более абстрактным и более удобным для использования в вызывающем коде. Такой подход широко используется в объектно-ориентированном программировании.

